<?xml version="1.0"?>
<robot name="gantry_robot">

  <link name="base_link">
    <visual>
      <geometry>
        <box size="1 1 0.1"/>
      </geometry>
    </visual>
  </link>

  <link name = "workstation">
  </link>

  <joint name = "transformation" type = "fixed">
  <parent link = "base_link"/>
  <child link = "workstation"/>
  <origin xyz = "0 0 0" rpy ="0 0 0"/>
  </joint>

  <!-- Virtual Link 1 -->
  <link name="virtual_link_1"/>

  <!-- z-axis prismatic joint -->
  <joint name="z_joint" type="prismatic">
    <parent link="base_link"/>
    <child link="virtual_link_1"/>
    <origin xyz="0 0 0" rpy="0 0 0"/>
    <axis xyz="0 0 1"/>
    <limit lower="0" upper="5" effort="0" velocity="0.5"/>
  </joint>


  <!-- X-axis slider -->
  <joint name="x_joint" type="prismatic">
    <parent link="virtual_link_1"/>
    <child link="x_slider"/>
    <origin xyz="0 0 0" rpy="0 0 0"/>
    <axis xyz="1 0 0"/>
    <limit lower="0" upper="5" effort="0" velocity="0.5"/>
  </joint>

  <link name="x_slider">
    <visual>
      <geometry>
        <box size="0.2 0.2 0.1"/>
      </geometry>
    </visual>
  </link>

  <!-- Y-axis slider -->
  <joint name="y_joint" type="prismatic">
    <parent link="x_slider"/>
    <child link="y_slider"/>
    <origin xyz="0 0 0" rpy="0 0 0"/>
    <axis xyz="0 1 0"/>
    <limit lower="0" upper="6" effort="0" velocity="0.5"/>
  </joint>

  <link name="y_slider">
    <visual>
      <geometry>
        <box size="0.2 0.2 0.1"/>
      </geometry>
    </visual>
  </link>

  <!-- End Effector -->
  <link name="end_effector">
    <visual>
      <geometry>
        <sphere radius="0.1"/>
      </geometry>
      <material name="orange">
        <color rgba="1 0.5 0 1"/>
      </material>
    </visual>
  </link>

  <joint name="end_effector_joint" type="fixed">
    <parent link="y_slider"/>
    <child link="end_effector"/>
    <origin xyz="0 0 0" rpy="0 0 0"/>
  </joint>

</robot>
